2024-01-07 13:17:43,760 [__main__:INFO] [main.py <23>: main.<module>] Logger successfully installed
2024-01-07 13:17:43,760 [__main__:INFO] [main.py <24>: main.<module>] Starting bot
2024-01-07 13:17:47,388 [__main__:INFO] [main.py <32>: main.start] Connected to datebase(user_base) for userid=788207542
2024-01-07 13:17:47,390 [__main__:ERROR] [main.py <41>: main.start] Insert to database(user_base) ERROR: values=788207542, Илья exception=UNIQUE constraint failed: base.user_id
2024-01-07 13:19:57,167 [__main__:INFO] [main.py <32>: main.start] Connected to datebase(user_base) for userid=788207542
2024-01-07 13:19:57,168 [__main__:ERROR] [main.py <41>: main.start] Insert to database(user_base) ERROR: values=788207542, Илья exception=UNIQUE constraint failed: base.user_id
