2024-01-07 13:16:43,639 [__main__:INFO] [main.py <23>: main.<module>] Logger successfully installed
2024-01-07 13:16:43,639 [__main__:INFO] [main.py <24>: main.<module>] Starting bot
2024-01-07 13:16:50,384 [__main__:INFO] [main.py <32>: main.start] Connected to datebase(user_base) for userid=788207542
2024-01-07 13:16:50,385 [__main__:ERROR] [main.py <41>: main.start] Insert to database(user_base) ERROR: values=788207542, Илья exception=UNIQUE constraint failed: base.user_id
