2024-01-07 13:39:49,821 [__main__:INFO] [main.py <23>: main.<module>] Logger successfully installed
2024-01-07 13:39:49,822 [__main__:INFO] [main.py <24>: main.<module>] Starting bot
2024-01-07 13:39:50,048 [__main__:INFO] [main.py <69>: main.statistics] Connected to datebase(user_base) for userid=788207542
2024-01-07 13:39:50,049 [__main__:ERROR] [main.py <78>: main.statistics] Select from database(user_base) ERROR: values=accepted, wrong_answer exception=row value misused
2024-01-07 13:39:50,050 [__main__:DEBUG] [main.py <79>: main.statistics] Reply statistics for userid=788207542
